<mujoco model="planar point mass">
  <asset>
      <texture name="skybox" type="skybox" builtin="gradient" rgb1=".4 .6 .8" rgb2="0 0 0"
               width="800" height="800" mark="random" markrgb="1 1 1"/>
      <texture name="grid" type="2d" builtin="checker" rgb1=".1 .2 .3" rgb2=".2 .3 .4" width="300" height="300" mark="edge" markrgb=".2 .3 .4"/>
      <material name="grid" texture="grid" texrepeat="1 1" texuniform="true" reflectance=".2"/>
      <material name="decoration" rgba=".3 .5 .7 1"/>
      <material name="target" rgba=".6 .3 .3 1"/>
      <material name="target_default" rgba=".6 .3 .3 1"/>
      <material name="target_highlight" rgba=".6 .3 .3 .4"/>
  </asset>

  <visual>
    <headlight ambient=".4 .4 .4" diffuse=".8 .8 .8" specular="0.1 0.1 0.1"/>
    <map znear=".01"/>
    <quality shadowsize="2048"/>
  </visual>

  <option timestep="0.02">
    <flag contact="disable"/>
  </option>

  <worldbody>
    <light name="light" pos="0 0 1"/>
    <camera name="fixed" pos="0 0 .75" quat="1 0 0 0"/>
    <geom name="ground" type="plane" pos="0 0 0" size=".3 .3 .1" material="grid"/>
    <geom name="wall_x" type="plane" pos="-.3 0 .02" zaxis="1 0 0"  size=".02 .3 .02" material="decoration"/>
    <geom name="wall_y" type="plane" pos="0 -.3 .02" zaxis="0 1 0"  size=".3 .02 .02" material="decoration"/>
    <geom name="wall_neg_x" type="plane" pos=".3 0 .02" zaxis="-1 0 0"  size=".02 .3 .02" material="decoration"/>
    <geom name="wall_neg_y" type="plane" pos="0 .3 .02" zaxis="0 -1 0"  size=".3 .02 .02" material="decoration"/>

    <body name="root">
      <body name="pointmass" pos="0 0 .01">
        <joint name="root_x" type="slide"  pos="0 0 0" axis="1 0 0" limited="true" range="-.29 .29" damping="1"/>
        <joint name="root_y" type="slide"  pos="0 0 0" axis="0 1 0" limited="true" range="-.29 .29" damping="1"/>
        <geom name="pointmass" type="sphere" size=".01" material="self" mass=".3"/>
      </body>
    </body>
  </worldbody>

  <tendon>
    <fixed name="t1">
      <joint joint="root_x" coef="1"/>
      <joint joint="root_y" coef="0"/>
    </fixed>
    <fixed name="t2">
      <joint joint="root_x" coef="0"/>
      <joint joint="root_y" coef="1"/>
    </fixed>
  </tendon>

  <actuator>
    <motor name="t1" tendon="t1" gear=".1" ctrlrange="-1 1" ctrllimited="true"/>
    <motor name="t2" tendon="t2" gear=".1" ctrlrange="-1 1" ctrllimited="true"/>
  </actuator>
</mujoco>